Workbook

Sheet Data Bulanan
A1: DATA PEMAKAIAN BULANAN & HARIAN BAHAN BAKU — PT. JJ Top Cosmindo Sidoarjo (2021–2025)
A2: σ_d dihitung dari 60 nilai d_harian (12 bulan × 5 tahun) per bahan · d_harian = Pemakaian Bulanan ÷ Hari/Bulan · Warna KUNING = input/turunan aktual · Warna HIJAU = formula Excel · Warna MERAH MUDA = σ_d (dipakai di sheet Data Historis)
A3: No | B3: Kode | C3: Nama Bahan Baku | D3: Satuan | E3: TAHUN 2021 | AE3: TAHUN 2022 | BE3: TAHUN 2023 | CE3: TAHUN 2024 | DE3: TAHUN 2025 | EE3: σ_d Global (Std Dev d_harian 5 Tahun × 12 Bln)
E4: Jan | G4: Feb | I4: Mar | K4: Apr | M4: Mei | O4: Jun | Q4: Jul | S4: Agu | U4: Sep | W4: Okt | Y4: Nov | AA4: Des | AC4: Total Pemakaian (unit/thn) | AD4: σ_d 2021 | AE4: Jan | AG4: Feb | AI4: Mar | AK4: Apr | AM4: Mei | AO4: Jun | AQ4: Jul | AS4: Agu | AU4: Sep | AW4: Okt | AY4: Nov | BA4: Des | BC4: Total Pemakaian (unit/thn) | BD4: σ_d 2022 | BE4: Jan | BG4: Feb | BI4: Mar | BK4: Apr | BM4: Mei | BO4: Jun | BQ4: Jul | BS4: Agu | BU4: Sep | BW4: Okt | BY4: Nov | CA4: Des | CC4: Total Pemakaian (unit/thn) | CD4: σ_d 2023 | CE4: Jan | CG4: Feb | CI4: Mar | CK4: Apr | CM4: Mei | CO4: Jun | CQ4: Jul | CS4: Agu | CU4: Sep | CW4: Okt | CY4: Nov | DA4: Des | DC4: Total Pemakaian (unit/thn) | DD4: σ_d 2024 | DE4: Jan | DG4: Feb | DI4: Mar | DK4: Apr | DM4: Mei | DO4: Jun | DQ4: Jul | DS4: Agu | DU4: Sep | DW4: Okt | DY4: Nov | EA4: Des | EC4: Total Pemakaian (unit/thn) | ED4: σ_d 2025
E5: Pemakaian (unit/31hr) | F5: d_harian (unit/hr) | G5: Pemakaian (unit/28hr) | H5: d_harian (unit/hr) | I5: Pemakaian (unit/31hr) | J5: d_harian (unit/hr) | K5: Pemakaian (unit/30hr) | L5: d_harian (unit/hr) | M5: Pemakaian (unit/31hr) | N5: d_harian (unit/hr) | O5: Pemakaian (unit/30hr) | P5: d_harian (unit/hr) | Q5: Pemakaian (unit/31hr) | R5: d_harian (unit/hr) | S5: Pemakaian (unit/31hr) | T5: d_harian (unit/hr) | U5: Pemakaian (unit/30hr) | V5: d_harian (unit/hr) | W5: Pemakaian (unit/31hr) | X5: d_harian (unit/hr) | Y5: Pemakaian (unit/30hr) | Z5: d_harian (unit/hr) | AA5: Pemakaian (unit/31hr) | AB5: d_harian (unit/hr) | AE5: Pemakaian (unit/31hr) | AF5: d_harian (unit/hr) | AG5: Pemakaian (unit/28hr) | AH5: d_harian (unit/hr) | AI5: Pemakaian (unit/31hr) | AJ5: d_harian (unit/hr) | AK5: Pemakaian (unit/30hr) | AL5: d_harian (unit/hr) | AM5: Pemakaian (unit/31hr) | AN5: d_harian (unit/hr) | AO5: Pemakaian (unit/30hr) | AP5: d_harian (unit/hr) | AQ5: Pemakaian (unit/31hr) | AR5: d_harian (unit/hr) | AS5: Pemakaian (unit/31hr) | AT5: d_harian (unit/hr) | AU5: Pemakaian (unit/30hr) | AV5: d_harian (unit/hr) | AW5: Pemakaian (unit/31hr) | AX5: d_harian (unit/hr) | AY5: Pemakaian (unit/30hr) | AZ5: d_harian (unit/hr) | BA5: Pemakaian (unit/31hr) | BB5: d_harian (unit/hr) | BE5: Pemakaian (unit/31hr) | BF5: d_harian (unit/hr) | BG5: Pemakaian (unit/28hr) | BH5: d_harian (unit/hr) | BI5: Pemakaian (unit/31hr) | BJ5: d_harian (unit/hr) | BK5: Pemakaian (unit/30hr) | BL5: d_harian (unit/hr) | BM5: Pemakaian (unit/31hr) | BN5: d_harian (unit/hr) | BO5: Pemakaian (unit/30hr) | BP5: d_harian (unit/hr) | BQ5: Pemakaian (unit/31hr) | BR5: d_harian (unit/hr) | BS5: Pemakaian (unit/31hr) | BT5: d_harian (unit/hr) | BU5: Pemakaian (unit/30hr) | BV5: d_harian (unit/hr) | BW5: Pemakaian (unit/31hr) | BX5: d_harian (unit/hr) | BY5: Pemakaian (unit/30hr) | BZ5: d_harian (unit/hr) | CA5: Pemakaian (unit/31hr) | CB5: d_harian (unit/hr) | CE5: Pemakaian (unit/31hr) | CF5: d_harian (unit/hr) | CG5: Pemakaian (unit/28hr) | CH5: d_harian (unit/hr) | CI5: Pemakaian (unit/31hr) | CJ5: d_harian (unit/hr) | CK5: Pemakaian (unit/30hr) | CL5: d_harian (unit/hr) | CM5: Pemakaian (unit/31hr) | CN5: d_harian (unit/hr) | CO5: Pemakaian (unit/30hr) | CP5: d_harian (unit/hr) | CQ5: Pemakaian (unit/31hr) | CR5: d_harian (unit/hr) | CS5: Pemakaian (unit/31hr) | CT5: d_harian (unit/hr) | CU5: Pemakaian (unit/30hr) | CV5: d_harian (unit/hr) | CW5: Pemakaian (unit/31hr) | CX5: d_harian (unit/hr) | CY5: Pemakaian (unit/30hr) | CZ5: d_harian (unit/hr) | DA5: Pemakaian (unit/31hr) | DB5: d_harian (unit/hr) | DE5: Pemakaian (unit/31hr) | DF5: d_harian (unit/hr) | DG5: Pemakaian (unit/28hr) | DH5: d_harian (unit/hr) | DI5: Pemakaian (unit/31hr) | DJ5: d_harian (unit/hr) | DK5: Pemakaian (unit/30hr) | DL5: d_harian (unit/hr) | DM5: Pemakaian (unit/31hr) | DN5: d_harian (unit/hr) | DO5: Pemakaian (unit/30hr) | DP5: d_harian (unit/hr) | DQ5: Pemakaian (unit/31hr) | DR5: d_harian (unit/hr) | DS5: Pemakaian (unit/31hr) | DT5: d_harian (unit/hr) | DU5: Pemakaian (unit/30hr) | DV5: d_harian (unit/hr) | DW5: Pemakaian (unit/31hr) | DX5: d_harian (unit/hr) | DY5: Pemakaian (unit/30hr) | DZ5: d_harian (unit/hr) | EA5: Pemakaian (unit/31hr) | EB5: d_harian (unit/hr)
A6: 1 | B6: BB001 | C6: Phenoxyethanol | D6: kg | E6: 3725 | F6: =E6/31 -> 120.16129 | G6: 2078 | H6: =G6/28 -> 74.214286 | I6: 2748 | J6: =I6/31 -> 88.645161 | K6: 2609 | L6: =K6/30 -> 86.966667 | M6: 3985 | N6: =M6/31 -> 128.54839 | O6: 3825 | P6: =O6/30 -> 127.5 | Q6: 4403 | R6: =Q6/31 -> 142.03226 | S6: 2244 | T6: =S6/31 -> 72.387097 | U6: 3142 | V6: =U6/30 -> 104.73333 | W6: 2091 | X6: =W6/31 -> 67.451613 | Y6: 2597 | Z6: =Y6/30 -> 86.566667 | AA6: 3366 | AB6: =AA6/31 -> 108.58065 | AC6: =SUM(E6:AA6) -> 37912.207 | AD6: =IFERROR(STDEV(F6,H6,J6,L6,N6,P6,R6,T6,V6,X6,Z6,AB6),0) -> 24.865922 | AE6: 1966 | AF6: =AE6/31 -> 63.419355 | AG6: 2402 | AH6: =AG6/28 -> 85.785714 | AI6: 3544 | AJ6: =AI6/31 -> 114.32258 | AK6: 3278 | AL6: =AK6/30 -> 109.26667 | AM6: 2457 | AN6: =AM6/31 -> 79.258065 | AO6: 3391 | AP6: =AO6/30 -> 113.03333 | AQ6: 3948 | AR6: =AQ6/31 -> 127.35484 | AS6: 1915 | AT6: =AS6/31 -> 61.774194 | AU6: 3939 | AV6: =AU6/30 -> 131.3 | AW6: 3666 | AX6: =AW6/31 -> 118.25806 | AY6: 2760 | AZ6: =AY6/30 -> 92 | BA6: 2292 | BB6: =BA6/31 -> 73.935484 | BC6: =SUM(AE6:BA6) -> 36653.773 | BD6: =IFERROR(STDEV(AF6,AH6,AJ6,AL6,AN6,AP6,AR6,AT6,AV6,AX6,AZ6,BB6),0) -> 24.53334 | BE6: 4043 | BF6: =BE6/31 -> 130.41935 | BG6: 2574 | BH6: =BG6/28 -> 91.928571 | BI6: 1996 | BJ6: =BI6/31 -> 64.387097 | BK6: 2005 | BL6: =BK6/30 -> 66.833333 | BM6: 3784 | BN6: =BM6/31 -> 122.06452 | BO6: 3206 | BP6: =BO6/30 -> 106.86667 | BQ6: 3688 | BR6: =BQ6/31 -> 118.96774 | BS6: 3505 | BT6: =BS6/31 -> 113.06452 | BU6: 3046 | BV6: =BU6/30 -> 101.53333 | BW6: 4081 | BX6: =BW6/31 -> 131.64516 | BY6: 2673 | BZ6: =BY6/30 -> 89.1 | CA6: 3084 | CB6: =CA6/31 -> 99.483871 | CC6: =SUM(BE6:CA6) -> 38821.81 | CD6: =IFERROR(STDEV(BF6,BH6,BJ6,BL6,BN6,BP6,BR6,BT6,BV6,BX6,BZ6,CB6),0) -> 22.230843 | CE6: 4507 | CF6: =CE6/31 -> 145.3871 | CG6: 3906 | CH6: =CG6/28 -> 139.5 | CI6: 4600 | CJ6: =CI6/31 -> 148.3871 | CK6: 3788 | CL6: =CK6/30 -> 126.26667 | CM6: 4151 | CN6: =CM6/31 -> 133.90323 | CO6: 2271 | CP6: =CO6/30 -> 75.7 | CQ6: 2791 | CR6: =CQ6/31 -> 90.032258 | CS6: 2966 | CT6: =CS6/31 -> 95.677419 | CU6: 2368 | CV6: =CU6/30 -> 78.933333 | CW6: 2805 | CX6: =CW6/31 -> 90.483871 | CY6: 2429 | CZ6: =CY6/30 -> 80.966667 | DA6: 2934 | DB6: =DA6/31 -> 94.645161 | DC6: =SUM(CE6:DA6) -> 40721.238 | DD6: =IFERROR(STDEV(CF6,CH6,CJ6,CL6,CN6,CP6,CR6,CT6,CV6,CX6,CZ6,DB6),0) -> 27.966488 | DE6: 2948 | DF6: =DE6/31 -> 95.096774 | DG6: 2372 | DH6: =DG6/28 -> 84.714286 | DI6: 2383 | DJ6: =DI6/31 -> 76.870968 | DK6: 2041 | DL6: =DK6/30 -> 68.033333 | DM6: 2163 | DN6: =DM6/31 -> 69.774194 | DO6: 3588 | DP6: =DO6/30 -> 119.6 | DQ6: 2974 | DR6: =DQ6/31 -> 95.935484 | DS6: 2891 | DT6: =DS6/31 -> 93.258065 | DU6: 1960 | DV6: =DU6/30 -> 65.333333 | DW6: 3147 | DX6: =DW6/31 -> 101.51613 | DY6: 1943 | DZ6: =DY6/30 -> 64.766667 | EA6: 2403 | EB6: =EA6/31 -> 77.516129 | EC6: =SUM(DE6:EA6) -> 31747.899 | ED6: =IFERROR(STDEV(DF6,DH6,DJ6,DL6,DN6,DP6,DR6,DT6,DV6,DX6,DZ6,EB6),0) -> 17.037135 | EE6: =STDEV(F6:AB6,AF6:BB6,BF6:CB6,CF6:DB6,DF6:EB6) -> 1523.1255
A7: 2 | B7: BB002 | C7: Glycerin | D7: kg | E7: 4411 | F7: =E7/31 -> 142.29032 | G7: 3524 | H7: =G7/28 -> 125.85714 | I7: 3314 | J7: =I7/31 -> 106.90323 | K7: 3637 | L7: =K7/30 -> 121.23333 | M7: 4039 | N7: =M7/31 -> 130.29032 | O7: 3869 | P7: =O7/30 -> 128.96667 | Q7: 2482 | R7: =Q7/31 -> 80.064516 | S7: 1983 | T7: =S7/31 -> 63.967742 | U7: 2701 | V7: =U7/30 -> 90.033333 | W7: 2580 | X7: =W7/31 -> 83.225806 | Y7: 2437 | Z7: =Y7/30 -> 81.233333 | AA7: 4292 | AB7: =AA7/31 -> 138.45161 | AC7: =SUM(E7:AA7) -> 40423.066 | AD7: =IFERROR(STDEV(F7,H7,J7,L7,N7,P7,R7,T7,V7,X7,Z7,AB7),0) -> 26.809131 | AE7: 4644 | AF7: =AE7/31 -> 149.80645 | AG7: 3040 | AH7: =AG7/28 -> 108.57143 | AI7: 4013 | AJ7: =AI7/31 -> 129.45161 | AK7: 3271 | AL7: =AK7/30 -> 109.03333 | AM7: 4753 | AN7: =AM7/31 -> 153.32258 | AO7: 3452 | AP7: =AO7/30 -> 115.06667 | AQ7: 2898 | AR7: =AQ7/31 -> 93.483871 | AS7: 2846 | AT7: =AS7/31 -> 91.806452 | AU7: 3744 | AV7: =AU7/30 -> 124.8 | AW7: 2892 | AX7: =AW7/31 -> 93.290323 | AY7: 3811 | AZ7: =AY7/30 -> 127.03333 | BA7: 4705 | BB7: =BA7/31 -> 151.77419 | BC7: =SUM(AE7:BA7) -> 45364.666 | BD7: =IFERROR(STDEV(AF7,AH7,AJ7,AL7,AN7,AP7,AR7,AT7,AV7,AX7,AZ7,BB7),0) -> 22.668063 | BE7: 3677 | BF7: =BE7/31 -> 118.6129 | BG7: 3101 | BH7: =BG7/28 -> 110.75 | BI7: 5590 | BJ7: =BI7/31 -> 180.32258 | BK7: 4029 | BL7: =BK7/30 -> 134.3 | BM7: 2690 | BN7: =BM7/31 -> 86.774194 | BO7: 2550 | BP7: =BO7/30 -> 85 | BQ7: 2750 | BR7: =BQ7/31 -> 88.709677 | BS7: 4406 | BT7: =BS7/31 -> 142.12903 | BU7: 4933 | BV7: =BU7/30 -> 164.43333 | BW7: 3750 | BX7: =BW7/31 -> 120.96774 | BY7: 2602 | BZ7: =BY7/30 -> 86.733333 | CA7: 3620 | CB7: =CA7/31 -> 116.77419 | CC7: =SUM(BE7:CA7) -> 45016.733 | CD7: =IFERROR(STDEV(BF7,BH7,BJ7,BL7,BN7,BP7,BR7,BT7,BV7,BX7,BZ7,CB7),0) -> 31.361782 | CE7: 3854 | CF7: =CE7/31 -> 124.32258 | CG7: 2823 | CH7: =CG7/28 -> 100.82143 | CI7: 3799 | CJ7: =CI7/31 -> 122.54839 | CK7: 3556 | CL7: =CK7/30 -> 118.53333 | CM7: 1681 | CN7: =CM7/31 -> 54.225806 | CO7: 3246 | CP7: =CO7/30 -> 108.2 | CQ7: 3160 | CR7: =CQ7/31 -> 101.93548 | CS7: 2841 | CT7: =CS7/31 -> 91.645161 | CU7: 2245 | CV7: =CU7/30 -> 74.833333 | CW7: 3070 | CX7: =CW7/31 -> 99.032258 | CY7: 1902 | CZ7: =CY7/30 -> 63.4 | DA7: 2615 | DB7: =DA7/31 -> 84.354839 | DC7: =SUM(CE7:DA7) -> 35851.498 | DD7: =IFERROR(STDEV(CF7,CH7,CJ7,CL7,CN7,CP7,CR7,CT7,CV7,CX7,CZ7,DB7),0) -> 22.635774 | DE7: 2611 | DF7: =DE7/31 -> 84.225806 | DG7: 3695 | DH7: =DG7/28 -> 131.96429 | DI7: 3526 | DJ7: =DI7/31 -> 113.74194 | DK7: 2198 | DL7: =DK7/30 -> 73.266667 | DM7: 2712 | DN7: =DM7/31 -> 87.483871 | DO7: 2014 | DP7: =DO7/30 -> 67.133333 | DQ7: 3606 | DR7: =DQ7/31 -> 116.32258 | DS7: 3515 | DT7: =DS7/31 -> 113.3871 | DU7: 2274 | DV7: =DU7/30 -> 75.8 | DW7: 3012 | DX7: =DW7/31 -> 97.16129 | DY7: 2947 | DZ7: =DY7/30 -> 98.233333 | EA7: 1958 | EB7: =EA7/31 -> 63.16129 | EC7: =SUM(DE7:EA7) -> 35126.72 | ED7: =IFERROR(STDEV(DF7,DH7,DJ7,DL7,DN7,DP7,DR7,DT7,DV7,DX7,DZ7,EB7),0) -> 21.95436 | EE7: =STDEV(F7:AB7,AF7:BB7,BF7:CB7,CF7:DB7,DF7:EB7) -> 1658.0651
A8: 3 | B8: BB003 | C8: Cetyl Alcohol | D8: kg | E8: 3492 | F8: =E8/31 -> 112.64516 | G8: 2977 | H8: =G8/28 -> 106.32143 | I8: 3529 | J8: =I8/31 -> 113.83871 | K8: 2956 | L8: =K8/30 -> 98.533333 | M8: 1733 | N8: =M8/31 -> 55.903226 | O8: 2480 | P8: =O8/30 -> 82.666667 | Q8: 1776 | R8: =Q8/31 -> 57.290323 | S8: 3877 | T8: =S8/31 -> 125.06452 | U8: 3760 | V8: =U8/30 -> 125.33333 | W8: 3652 | X8: =W8/31 -> 117.80645 | Y8: 2441 | Z8: =Y8/30 -> 81.366667 | AA8: 1865 | AB8: =AA8/31 -> 60.16129 | AC8: =SUM(E8:AA8) -> 35614.77 | AD8: =IFERROR(STDEV(F8,H8,J8,L8,N8,P8,R8,T8,V8,X8,Z8,AB8),0) -> 26.375842 | AE8: 2938 | AF8: =AE8/31 -> 94.774194 | AG8: 3062 | AH8: =AG8/28 -> 109.35714 | AI8: 1508 | AJ8: =AI8/31 -> 48.645161 | AK8: 2230 | AL8: =AK8/30 -> 74.333333 | AM8: 1478 | AN8: =AM8/31 -> 47.677419 | AO8: 2726 | AP8: =AO8/30 -> 90.866667 | AQ8: 2735 | AR8: =AQ8/31 -> 88.225806 | AS8: 1585 | AT8: =AS8/31 -> 51.129032 | AU8: 2211 | AV8: =AU8/30 -> 73.7 | AW8: 2346 | AX8: =AW8/31 -> 75.677419 | AY8: 1832 | AZ8: =AY8/30 -> 61.066667 | BA8: 2928 | BB8: =BA8/31 -> 94.451613 | BC8: =SUM(AE8:BA8) -> 28394.453 | BD8: =IFERROR(STDEV(AF8,AH8,AJ8,AL8,AN8,AP8,AR8,AT8,AV8,AX8,AZ8,BB8),0) -> 20.395968 | BE8: 2325 | BF8: =BE8/31 -> 75 | BG8: 1906 | BH8: =BG8/28 -> 68.071429 | BI8: 2555 | BJ8: =BI8/31 -> 82.419355 | BK8: 2933 | BL8: =BK8/30 -> 97.766667 | BM8: 1885 | BN8: =BM8/31 -> 60.806452 | BO8: 2104 | BP8: =BO8/30 -> 70.133333 | BQ8: 3459 | BR8: =BQ8/31 -> 111.58065 | BS8: 2775 | BT8: =BS8/31 -> 89.516129 | BU8: 2355 | BV8: =BU8/30 -> 78.5 | BW8: 2512 | BX8: =BW8/31 -> 81.032258 | BY8: 1726 | BZ8: =BY8/30 -> 57.533333 | CA8: 1932 | CB8: =CA8/31 -> 62.322581 | CC8: =SUM(BE8:CA8) -> 29339.36 | CD8: =IFERROR(STDEV(BF8,BH8,BJ8,BL8,BN8,BP8,BR8,BT8,BV8,BX8,BZ8,CB8),0) -> 15.981744 | CE8: 2042 | CF8: =CE8/31 -> 65.870968 | CG8: 2511 | CH8: =CG8/28 -> 89.678571 | CI8: 1839 | CJ8: =CI8/31 -> 59.322581 | CK8: 1821 | CL8: =CK8/30 -> 60.7 | CM8: 1541 | CN8: =CM8/31 -> 49.709677 | CO8: 2592 | CP8: =CO8/30 -> 86.4 | CQ8: 1837 | CR8: =CQ8/31 -> 59.258065 | CS8: 3107 | CT8: =CS8/31 -> 100.22581 | CU8: 3021 | CV8: =CU8/30 -> 100.7 | CW8: 1540 | CX8: =CW8/31 -> 49.677419 | CY8: 1854 | CZ8: =CY8/30 -> 61.8 | DA8: 2663 | DB8: =DA8/31 -> 85.903226 | DC8: =SUM(CE8:DA8) -> 27151.343 | DD8: =IFERROR(STDEV(CF8,CH8,CJ8,CL8,CN8,CP8,CR8,CT8,CV8,CX8,CZ8,DB8),0) -> 18.874728 | DE8: 2107 | DF8: =DE8/31 -> 67.967742 | DG8: 1928 | DH8: =DG8/28 -> 68.857143 | DI8: 3683 | DJ8: =DI8/31 -> 118.80645 | DK8: 2887 | DL8: =DK8/30 -> 96.233333 | DM8: 2672 | DN8: =DM8/31 -> 86.193548 | DO8: 3354 | DP8: =DO8/30 -> 111.8 | DQ8: 3404 | DR8: =DQ8/31 -> 109.80645 | DS8: 2055 | DT8: =DS8/31 -> 66.290323 | DU8: 1851 | DV8: =DU8/30 -> 61.7 | DW8: 2581 | DX8: =DW8/31 -> 83.258065 | DY8: 2565 | DZ8: =DY8/30 -> 85.5 | EA8: 2660 | EB8: =EA8/31 -> 85.806452 | EC8: =SUM(DE8:EA8) -> 32703.413 | ED8: =IFERROR(STDEV(DF8,DH8,DJ8,DL8,DN8,DP8,DR8,DT8,DV8,DX8,DZ8,EB8),0) -> 19.094294 | EE8: =STDEV(F8:AB8,AF8:BB8,BF8:CB8,CF8:DB8,DF8:EB8) -> 1280.2654
A9: 4 | B9: BB004 | C9: Stearic Acid | D9: kg | E9: 3617 | F9: =E9/31 -> 116.67742 | G9: 3481 | H9: =G9/28 -> 124.32143 | I9: 4241 | J9: =I9/31 -> 136.80645 | K9: 2075 | L9: =K9/30 -> 69.166667 | M9: 2819 | N9: =M9/31 -> 90.935484 | O9: 2664 | P9: =O9/30 -> 88.8 | Q9: 3941 | R9: =Q9/31 -> 127.12903 | S9: 2442 | T9: =S9/31 -> 78.774194 | U9: 2299 | V9: =U9/30 -> 76.633333 | W9: 2931 | X9: =W9/31 -> 94.548387 | Y9: 2866 | Z9: =Y9/30 -> 95.533333 | AA9: 2515 | AB9: =AA9/31 -> 81.129032 | AC9: =SUM(E9:AA9) -> 36990.326 | AD9: =IFERROR(STDEV(F9,H9,J9,L9,N9,P9,R9,T9,V9,X9,Z9,AB9),0) -> 22.33862 | AE9: 2341 | AF9: =AE9/31 -> 75.516129 | AG9: 3919 | AH9: =AG9/28 -> 139.96429 | AI9: 2794 | AJ9: =AI9/31 -> 90.129032 | AK9: 3774 | AL9: =AK9/30 -> 125.8 | AM9: 3045 | AN9: =AM9/31 -> 98.225806 | AO9: 1875 | AP9: =AO9/30 -> 62.5 | AQ9: 4097 | AR9: =AQ9/31 -> 132.16129 | AS9: 3714 | AT9: =AS9/31 -> 119.80645 | AU9: 4026 | AV9: =AU9/30 -> 134.2 | AW9: 3926 | AX9: =AW9/31 -> 126.64516 | AY9: 3744 | AZ9: =AY9/30 -> 124.8 | BA9: 2146 | BB9: =BA9/31 -> 69.225806 | BC9: =SUM(AE9:BA9) -> 40630.748 | BD9: =IFERROR(STDEV(AF9,AH9,AJ9,AL9,AN9,AP9,AR9,AT9,AV9,AX9,AZ9,BB9),0) -> 27.668652 | BE9: 3060 | BF9: =BE9/31 -> 98.709677 | BG9: 2387 | BH9: =BG9/28 -> 85.25 | BI9: 2851 | BJ9: =BI9/31 -> 91.967742 | BK9: 2003 | BL9: =BK9/30 -> 66.766667 | BM9: 2796 | BN9: =BM9/31 -> 90.193548 | BO9: 4298 | BP9: =BO9/30 -> 143.26667 | BQ9: 2514 | BR9: =BQ9/31 -> 81.096774 | BS9: 3799 | BT9: =BS9/31 -> 122.54839 | BU9: 2984 | BV9: =BU9/30 -> 99.466667 | BW9: 2905 | BX9: =BW9/31 -> 93.709677 | BY9: 4228 | BZ9: =BY9/30 -> 140.93333 | CA9: 4323 | CB9: =CA9/31 -> 139.45161 | CC9: =SUM(BE9:CA9) -> 39261.909 | CD9: =IFERROR(STDEV(BF9,BH9,BJ9,BL9,BN9,BP9,BR9,BT9,BV9,BX9,BZ9,CB9),0) -> 25.684574 | CE9: 2782 | CF9: =CE9/31 -> 89.741935 | CG9: 3128 | CH9: =CG9/28 -> 111.71429 | CI9: 1927 | CJ9: =CI9/31 -> 62.16129 | CK9: 2230 | CL9: =CK9/30 -> 74.333333 | CM9: 3661 | CN9: =CM9/31 -> 118.09677 | CO9: 2832 | CP9: =CO9/30 -> 94.4 | CQ9: 2753 | CR9: =CQ9/31 -> 88.806452 | CS9: 3191 | CT9: =CS9/31 -> 102.93548 | CU9: 1720 | CV9: =CU9/30 -> 57.333333 | CW9: 2842 | CX9: =CW9/31 -> 91.677419 | CY9: 2669 | CZ9: =CY9/30 -> 88.966667 | DA9: 3414 | DB9: =DA9/31 -> 110.12903 | DC9: =SUM(CE9:DA9) -> 34129.167 | DD9: =IFERROR(STDEV(CF9,CH9,CJ9,CL9,CN9,CP9,CR9,CT9,CV9,CX9,CZ9,DB9),0) -> 18.918225 | DE9: 2126 | DF9: =DE9/31 -> 68.580645 | DG9: 4007 | DH9: =DG9/28 -> 143.10714 | DI9: 1945 | DJ9: =DI9/31 -> 62.741935 | DK9: 2192 | DL9: =DK9/30 -> 73.066667 | DM9: 3151 | DN9: =DM9/31 -> 101.64516 | DO9: 3339 | DP9: =DO9/30 -> 111.3 | DQ9: 2308 | DR9: =DQ9/31 -> 74.451613 | DS9: 2038 | DT9: =DS9/31 -> 65.741935 | DU9: 3842 | DV9: =DU9/30 -> 128.06667 | DW9: 2334 | DX9: =DW9/31 -> 75.290323 | DY9: 3150 | DZ9: =DY9/30 -> 105 | EA9: 3208 | EB9: =EA9/31 -> 103.48387 | EC9: =SUM(DE9:EA9) -> 34648.992 | ED9: =IFERROR(STDEV(DF9,DH9,DJ9,DL9,DN9,DP9,DR9,DT9,DV9,DX9,DZ9,EB9),0) -> 26.479448 | EE9: =STDEV(F9:AB9,AF9:BB9,BF9:CB9,CF9:DB9,DF9:EB9) -> 1552.9305
A10: 5 | B10: BB005 | C10: Titanium Dioxide | D10: kg | E10: 972 | F10: =E10/31 -> 31.354839 | G10: 1108 | H10: =G10/28 -> 39.571429 | I10: 1058 | J10: =I10/31 -> 34.129032 | K10: 1400 | L10: =K10/30 -> 46.666667 | M10: 793 | N10: =M10/31 -> 25.580645 | O10: 1219 | P10: =O10/30 -> 40.633333 | Q10: 822 | R10: =Q10/31 -> 26.516129 | S10: 952 | T10: =S10/31 -> 30.709677 | U10: 1182 | V10: =U10/30 -> 39.4 | W10: 873 | X10: =W10/31 -> 28.16129 | Y10: 886 | Z10: =Y10/30 -> 29.533333 | AA10: 1248 | AB10: =AA10/31 -> 40.258065 | AC10: =SUM(E10:AA10) -> 12885.256 | AD10: =IFERROR(STDEV(F10,H10,J10,L10,N10,P10,R10,T10,V10,X10,Z10,AB10),0) -> 6.7479738 | AE10: 803 | AF10: =AE10/31 -> 25.903226 | AG10: 1180 | AH10: =AG10/28 -> 42.142857 | AI10: 1707 | AJ10: =AI10/31 -> 55.064516 | AK10: 1705 | AL10: =AK10/30 -> 56.833333 | AM10: 804 | AN10: =AM10/31 -> 25.935484 | AO10: 940 | AP10: =AO10/30 -> 31.333333 | AQ10: 991 | AR10: =AQ10/31 -> 31.967742 | AS10: 1643 | AT10: =AS10/31 -> 53 | AU10: 1592 | AV10: =AU10/30 -> 53.066667 | AW10: 1591 | AX10: =AW10/31 -> 51.322581 | AY10: 1093 | AZ10: =AY10/30 -> 36.433333 | BA10: 886 | BB10: =BA10/31 -> 28.580645 | BC10: =SUM(AE10:BA10) -> 15398.003 | BD10: =IFERROR(STDEV(AF10,AH10,AJ10,AL10,AN10,AP10,AR10,AT10,AV10,AX10,AZ10,BB10),0) -> 12.2509 | BE10: 1400 | BF10: =BE10/31 -> 45.16129 | BG10: 1285 | BH10: =BG10/28 -> 45.892857 | BI10: 1204 | BJ10: =BI10/31 -> 38.83871 | BK10: 1536 | BL10: =BK10/30 -> 51.2 | BM10: 1242 | BN10: =BM10/31 -> 40.064516 | BO10: 670 | BP10: =BO10/30 -> 22.333333 | BQ10: 1386 | BR10: =BQ10/31 -> 44.709677 | BS10: 928 | BT10: =BS10/31 -> 29.935484 | BU10: 1250 | BV10: =BU10/30 -> 41.666667 | BW10: 1493 | BX10: =BW10/31 -> 48.16129 | BY10: 782 | BZ10: =BY10/30 -> 26.066667 | CA10: 765 | CB10: =CA10/31 -> 24.677419 | CC10: =SUM(BE10:CA10) -> 14375.03 | CD10: =IFERROR(STDEV(BF10,BH10,BJ10,BL10,BN10,BP10,BR10,BT10,BV10,BX10,BZ10,CB10),0) -> 9.9282351 | CE10: 811 | CF10: =CE10/31 -> 26.16129 | CG10: 1233 | CH10: =CG10/28 -> 44.035714 | CI10: 967 | CJ10: =CI10/31 -> 31.193548 | CK10: 1282 | CL10: =CK10/30 -> 42.733333 | CM10: 1389 | CN10: =CM10/31 -> 44.806452 | CO10: 902 | CP10: =CO10/30 -> 30.066667 | CQ10: 1310 | CR10: =CQ10/31 -> 42.258065 | CS10: 960 | CT10: =CS10/31 -> 30.967742 | CU10: 1172 | CV10: =CU10/30 -> 39.066667 | CW10: 1566 | CX10: =CW10/31 -> 50.516129 | CY10: 1510 | CZ10: =CY10/30 -> 50.333333 | DA10: 797 | DB10: =DA10/31 -> 25.709677 | DC10: =SUM(CE10:DA10) -> 14331.139 | DD10: =IFERROR(STDEV(CF10,CH10,CJ10,CL10,CN10,CP10,CR10,CT10,CV10,CX10,CZ10,DB10),0) -> 8.9586732 | DE10: 1204 | DF10: =DE10/31 -> 38.83871 | DG10: 1053 | DH10: =DG10/28 -> 37.607143 | DI10: 773 | DJ10: =DI10/31 -> 24.935484 | DK10: 1560 | DL10: =DK10/30 -> 52 | DM10: 1423 | DN10: =DM10/31 -> 45.903226 | DO10: 1038 | DP10: =DO10/30 -> 34.6 | DQ10: 1530 | DR10: =DQ10/31 -> 49.354839 | DS10: 1335 | DT10: =DS10/31 -> 43.064516 | DU10: 1208 | DV10: =DU10/30 -> 40.266667 | DW10: 779 | DX10: =DW10/31 -> 25.129032 | DY10: 847 | DZ10: =DY10/30 -> 28.233333 | EA10: 1675 | EB10: =EA10/31 -> 54.032258 | EC10: =SUM(DE10:EA10) -> 14844.933 | ED10: =IFERROR(STDEV(DF10,DH10,DJ10,DL10,DN10,DP10,DR10,DT10,DV10,DX10,DZ10,EB10),0) -> 9.9657001 | EE10: =STDEV(F10:AB10,AF10:BB10,BF10:CB10,CF10:DB10,DF10:EB10) -> 604.39845
A11: 6 | B11: BB006 | C11: Sodium Lauryl Sulfate | D11: kg | E11: 537 | F11: =E11/31 -> 17.322581 | G11: 421 | H11: =G11/28 -> 15.035714 | I11: 515 | J11: =I11/31 -> 16.612903 | K11: 433 | L11: =K11/30 -> 14.433333 | M11: 292 | N11: =M11/31 -> 9.4193548 | O11: 285 | P11: =O11/30 -> 9.5 | Q11: 344 | R11: =Q11/31 -> 11.096774 | S11: 536 | T11: =S11/31 -> 17.290323 | U11: 502 | V11: =U11/30 -> 16.733333 | W11: 523 | X11: =W11/31 -> 16.870968 | Y11: 536 | Z11: =Y11/30 -> 17.866667 | AA11: 312 | AB11: =AA11/31 -> 10.064516 | AC11: =SUM(E11:AA11) -> 5398.182 | AD11: =IFERROR(STDEV(F11,H11,J11,L11,N11,P11,R11,T11,V11,X11,Z11,AB11),0) -> 3.3610678 | AE11: 380 | AF11: =AE11/31 -> 12.258065 | AG11: 324 | AH11: =AG11/28 -> 11.571429 | AI11: 582 | AJ11: =AI11/31 -> 18.774194 | AK11: 621 | AL11: =AK11/30 -> 20.7 | AM11: 440 | AN11: =AM11/31 -> 14.193548 | AO11: 521 | AP11: =AO11/30 -> 17.366667 | AQ11: 344 | AR11: =AQ11/31 -> 11.096774 | AS11: 639 | AT11: =AS11/31 -> 20.612903 | AU11: 614 | AV11: =AU11/30 -> 20.466667 | AW11: 656 | AX11: =AW11/31 -> 21.16129 | AY11: 593 | AZ11: =AY11/30 -> 19.766667 | BA11: 620 | BB11: =BA11/31 -> 20 | BC11: =SUM(AE11:BA11) -> 6521.9682 | BD11: =IFERROR(STDEV(AF11,AH11,AJ11,AL11,AN11,AP11,AR11,AT11,AV11,AX11,AZ11,BB11),0) -> 3.9240656 | BE11: 239 | BF11: =BE11/31 -> 7.7096774 | BG11: 459 | BH11: =BG11/28 -> 16.392857 | BI11: 334 | BJ11: =BI11/31 -> 10.774194 | BK11: 519 | BL11: =BK11/30 -> 17.3 | BM11: 479 | BN11: =BM11/31 -> 15.451613 | BO11: 498 | BP11: =BO11/30 -> 16.6 | BQ11: 482 | BR11: =BQ11/31 -> 15.548387 | BS11: 314 | BT11: =BS11/31 -> 10.129032 | BU11: 475 | BV11: =BU11/30 -> 15.833333 | BW11: 265 | BX11: =BW11/31 -> 8.5483871 | BY11: 501 | BZ11: =BY11/30 -> 16.7 | CA11: 497 | CB11: =CA11/31 -> 16.032258 | CC11: =SUM(BE11:CA11) -> 5212.9875 | CD11: =IFERROR(STDEV(BF11,BH11,BJ11,BL11,BN11,BP11,BR11,BT11,BV11,BX11,BZ11,CB11),0) -> 3.5324472 | CE11: 438 | CF11: =CE11/31 -> 14.129032 | CG11: 705 | CH11: =CG11/28 -> 25.178571 | CI11: 545 | CJ11: =CI11/31 -> 17.580645 | CK11: 475 | CL11: =CK11/30 -> 15.833333 | CM11: 695 | CN11: =CM11/31 -> 22.419355 | CO11: 440 | CP11: =CO11/30 -> 14.666667 | CQ11: 348 | CR11: =CQ11/31 -> 11.225806 | CS11: 424 | CT11: =CS11/31 -> 13.677419 | CU11: 485 | CV11: =CU11/30 -> 16.166667 | CW11: 727 | CX11: =CW11/31 -> 23.451613 | CY11: 773 | CZ11: =CY11/30 -> 25.766667 | DA11: 463 | DB11: =DA11/31 -> 14.935484 | DC11: =SUM(CE11:DA11) -> 6718.0958 | DD11: =IFERROR(STDEV(CF11,CH11,CJ11,CL11,CN11,CP11,CR11,CT11,CV11,CX11,CZ11,DB11),0) -> 4.9480772 | DE11: 575 | DF11: =DE11/31 -> 18.548387 | DG11: 475 | DH11: =DG11/28 -> 16.964286 | DI11: 716 | DJ11: =DI11/31 -> 23.096774 | DK11: 532 | DL11: =DK11/30 -> 17.733333 | DM11: 699 | DN11: =DM11/31 -> 22.548387 | DO11: 358 | DP11: =DO11/30 -> 11.933333 | DQ11: 711 | DR11: =DQ11/31 -> 22.935484 | DS11: 384 | DT11: =DS11/31 -> 12.387097 | DU11: 708 | DV11: =DU11/30 -> 23.6 | DW11: 420 | DX11: =DW11/31 -> 13.548387 | DY11: 355 | DZ11: =DY11/30 -> 11.833333 | EA11: 490 | EB11: =EA11/31 -> 15.806452 | EC11: =SUM(DE11:EA11) -> 6618.1288 | ED11: =IFERROR(STDEV(DF11,DH11,DJ11,DL11,DN11,DP11,DR11,DT11,DV11,DX11,DZ11,EB11),0) -> 4.5989747 | EE11: =STDEV(F11:AB11,AF11:BB11,BF11:CB11,CF11:DB11,DF11:EB11) -> 258.07564
A12: 7 | B12: BB007 | C12: Propylene Glycol | D12: kg | E12: 1556 | F12: =E12/31 -> 50.193548 | G12: 1120 | H12: =G12/28 -> 40 | I12: 1428 | J12: =I12/31 -> 46.064516 | K12: 1328 | L12: =K12/30 -> 44.266667 | M12: 1195 | N12: =M12/31 -> 38.548387 | O12: 1396 | P12: =O12/30 -> 46.533333 | Q12: 1058 | R12: =Q12/31 -> 34.129032 | S12: 1536 | T12: =S12/31 -> 49.548387 | U12: 791 | V12: =U12/30 -> 26.366667 | W12: 1764 | X12: =W12/31 -> 56.903226 | Y12: 1356 | Z12: =Y12/30 -> 45.2 | AA12: 1547 | AB12: =AA12/31 -> 49.903226 | AC12: =SUM(E12:AA12) -> 16552.754 | AD12: =IFERROR(STDEV(F12,H12,J12,L12,N12,P12,R12,T12,V12,X12,Z12,AB12),0) -> 8.1840077 | AE12: 2060 | AF12: =AE12/31 -> 66.451613 | AG12: 1962 | AH12: =AG12/28 -> 70.071429 | AI12: 1539 | AJ12: =AI12/31 -> 49.645161 | AK12: 1132 | AL12: =AK12/30 -> 37.733333 | AM12: 1953 | AN12: =AM12/31 -> 63 | AO12: 1492 | AP12: =AO12/30 -> 49.733333 | AQ12: 1469 | AR12: =AQ12/31 -> 47.387097 | AS12: 2207 | AT12: =AS12/31 -> 71.193548 | AU12: 2030 | AV12: =AU12/30 -> 67.666667 | AW12: 1450 | AX12: =AW12/31 -> 46.774194 | AY12: 1463 | AZ12: =AY12/30 -> 48.766667 | BA12: 1600 | BB12: =BA12/31 -> 51.612903 | BC12: =SUM(AE12:BA12) -> 20975.423 | BD12: =IFERROR(STDEV(AF12,AH12,AJ12,AL12,AN12,AP12,AR12,AT12,AV12,AX12,AZ12,BB12),0) -> 11.148039 | BE12: 1579 | BF12: =BE12/31 -> 50.935484 | BG12: 1433 | BH12: =BG12/28 -> 51.178571 | BI12: 1202 | BJ12: =BI12/31 -> 38.774194 | BK12: 1603 | BL12: =BK12/30 -> 53.433333 | BM12: 2316 | BN12: =BM12/31 -> 74.709677 | BO12: 1955 | BP12: =BO12/30 -> 65.166667 | BQ12: 2264 | BR12: =BQ12/31 -> 73.032258 | BS12: 1871 | BT12: =BS12/31 -> 60.354839 | BU12: 1440 | BV12: =BU12/30 -> 48 | BW12: 1778 | BX12: =BW12/31 -> 57.354839 | BY12: 1028 | BZ12: =BY12/30 -> 34.266667 | CA12: 1421 | CB12: =CA12/31 -> 45.83871 | CC12: =SUM(BE12:CA12) -> 20497.207 | CD12: =IFERROR(STDEV(BF12,BH12,BJ12,BL12,BN12,BP12,BR12,BT12,BV12,BX12,BZ12,CB12),0) -> 12.456611 | CE12: 1637 | CF12: =CE12/31 -> 52.806452 | CG12: 1845 | CH12: =CG12/28 -> 65.892857 | CI12: 1949 | CJ12: =CI12/31 -> 62.870968 | CK12: 1685 | CL12: =CK12/30 -> 56.166667 | CM12: 1654 | CN12: =CM12/31 -> 53.354839 | CO12: 1337 | CP12: =CO12/30 -> 44.566667 | CQ12: 1697 | CR12: =CQ12/31 -> 54.741935 | CS12: 2291 | CT12: =CS12/31 -> 73.903226 | CU12: 2145 | CV12: =CU12/30 -> 71.5 | CW12: 1276 | CX12: =CW12/31 -> 41.16129 | CY12: 1158 | CZ12: =CY12/30 -> 38.6 | DA12: 1755 | DB12: =DA12/31 -> 56.612903 | DC12: =SUM(CE12:DA12) -> 21044.565 | DD12: =IFERROR(STDEV(CF12,CH12,CJ12,CL12,CN12,CP12,CR12,CT12,CV12,CX12,CZ12,DB12),0) -> 11.19538 | DE12: 1586 | DF12: =DE12/31 -> 51.16129 | DG12: 1244 | DH12: =DG12/28 -> 44.428571 | DI12: 1799 | DJ12: =DI12/31 -> 58.032258 | DK12: 1721 | DL12: =DK12/30 -> 57.366667 | DM12: 1632 | DN12: =DM12/31 -> 52.645161 | DO12: 1118 | DP12: =DO12/30 -> 37.266667 | DQ12: 1088 | DR12: =DQ12/31 -> 35.096774 | DS12: 888 | DT12: =DS12/31 -> 28.645161 | DU12: 1141 | DV12: =DU12/30 -> 38.033333 | DW12: 1405 | DX12: =DW12/31 -> 45.322581 | DY12: 1835 | DZ12: =DY12/30 -> 61.166667 | EA12: 944 | EB12: =EA12/31 -> 30.451613 | EC12: =SUM(DE12:EA12) -> 16910.165 | ED12: =IFERROR(STDEV(DF12,DH12,DJ12,DL12,DN12,DP12,DR12,DT12,DV12,DX12,DZ12,EB12),0) -> 11.145781 | EE12: =STDEV(F12:AB12,AF12:BB12,BF12:CB12,CF12:DB12,DF12:EB12) -> 790.35461
A13: 8 | B13: BB008 | C13: Carbomer 940 | D13: kg | E13: 3099 | F13: =E13/31 -> 99.967742 | G13: 3672 | H13: =G13/28 -> 131.14286 | I13: 2513 | J13: =I13/31 -> 81.064516 | K13: 3849 | L13: =K13/30 -> 128.3 | M13: 3311 | N13: =M13/31 -> 106.80645 | O13: 2645 | P13: =O13/30 -> 88.166667 | Q13: 3742 | R13: =Q13/31 -> 120.70968 | S13: 2011 | T13: =S13/31 -> 64.870968 | U13: 3994 | V13: =U13/30 -> 133.13333 | W13: 4045 | X13: =W13/31 -> 130.48387 | Y13: 2279 | Z13: =Y13/30 -> 75.966667 | AA13: 3127 | AB13: =AA13/31 -> 100.87097 | AC13: =SUM(E13:AA13) -> 39447.613 | AD13: =IFERROR(STDEV(F13,H13,J13,L13,N13,P13,R13,T13,V13,X13,Z13,AB13),0) -> 23.872844 | AE13: 2467 | AF13: =AE13/31 -> 79.580645 | AG13: 4551 | AH13: =AG13/28 -> 162.53571 | AI13: 3379 | AJ13: =AI13/31 -> 109 | AK13: 2132 | AL13: =AK13/30 -> 71.066667 | AM13: 2663 | AN13: =AM13/31 -> 85.903226 | AO13: 4259 | AP13: =AO13/30 -> 141.96667 | AQ13: 3215 | AR13: =AQ13/31 -> 103.70968 | AS13: 4134 | AT13: =AS13/31 -> 133.35484 | AU13: 3777 | AV13: =AU13/30 -> 125.9 | AW13: 4631 | AX13: =AW13/31 -> 149.3871 | AY13: 3585 | AZ13: =AY13/30 -> 119.5 | BA13: 4530 | BB13: =BA13/31 -> 146.12903 | BC13: =SUM(AE13:BA13) -> 44604.905 | BD13: =IFERROR(STDEV(AF13,AH13,AJ13,AL13,AN13,AP13,AR13,AT13,AV13,AX13,AZ13,BB13),0) -> 29.567777 | BE13: 4209 | BF13: =BE13/31 -> 135.77419 | BG13: 3494 | BH13: =BG13/28 -> 124.78571 | BI13: 3767 | BJ13: =BI13/31 -> 121.51613 | BK13: 3217 | BL13: =BK13/30 -> 107.23333 | BM13: 4053 | BN13: =BM13/31 -> 130.74194 | BO13: 3328 | BP13: =BO13/30 -> 110.93333 | BQ13: 4224 | BR13: =BQ13/31 -> 136.25806 | BS13: 3830 | BT13: =BS13/31 -> 123.54839 | BU13: 3140 | BV13: =BU13/30 -> 104.66667 | BW13: 2588 | BX13: =BW13/31 -> 83.483871 | BY13: 2557 | BZ13: =BY13/30 -> 85.233333 | CA13: 3558 | CB13: =CA13/31 -> 114.77419 | CC13: =SUM(BE13:CA13) -> 43229.175 | CD13: =IFERROR(STDEV(BF13,BH13,BJ13,BL13,BN13,BP13,BR13,BT13,BV13,BX13,BZ13,CB13),0) -> 17.595176 | CE13: 5751 | CF13: =CE13/31 -> 185.51613 | CG13: 4823 | CH13: =CG13/28 -> 172.25 | CI13: 5223 | CJ13: =CI13/31 -> 168.48387 | CK13: 3887 | CL13: =CK13/30 -> 129.56667 | CM13: 3139 | CN13: =CM13/31 -> 101.25806 | CO13: 3929 | CP13: =CO13/30 -> 130.96667 | CQ13: 3876 | CR13: =CQ13/31 -> 125.03226 | CS13: 4058 | CT13: =CS13/31 -> 130.90323 | CU13: 4895 | CV13: =CU13/30 -> 163.16667 | CW13: 3370 | CX13: =CW13/31 -> 108.70968 | CY13: 3723 | CZ13: =CY13/30 -> 124.1 | DA13: 5478 | DB13: =DA13/31 -> 176.70968 | DC13: =SUM(CE13:DA13) -> 53691.953 | DD13: =IFERROR(STDEV(CF13,CH13,CJ13,CL13,CN13,CP13,CR13,CT13,CV13,CX13,CZ13,DB13),0) -> 28.485186 | DE13: 4861 | DF13: =DE13/31 -> 156.80645 | DG13: 2718 | DH13: =DG13/28 -> 97.071429 | DI13: 3864 | DJ13: =DI13/31 -> 124.64516 | DK13: 4314 | DL13: =DK13/30 -> 143.8 | DM13: 3891 | DN13: =DM13/31 -> 125.51613 | DO13: 3193 | DP13: =DO13/30 -> 106.43333 | DQ13: 3905 | DR13: =DQ13/31 -> 125.96774 | DS13: 5523 | DT13: =DS13/31 -> 178.16129 | DU13: 4453 | DV13: =DU13/30 -> 148.43333 | DW13: 4825 | DX13: =DW13/31 -> 155.64516 | DY13: 5363 | DZ13: =DY13/30 -> 178.76667 | EA13: 5058 | EB13: =EA13/31 -> 163.16129 | EC13: =SUM(DE13:EA13) -> 53509.247 | ED13: =IFERROR(STDEV(DF13,DH13,DJ13,DL13,DN13,DP13,DR13,DT13,DV13,DX13,DZ13,EB13),0) -> 26.407245 | EE13: =STDEV(F13:AB13,AF13:BB13,BF13:CB13,CF13:DB13,DF13:EB13) -> 1918.7702
A14: 9 | B14: BB009 | C14: Kaolin Clay | D14: kg | E14: 3358 | F14: =E14/31 -> 108.32258 | G14: 2246 | H14: =G14/28 -> 80.214286 | I14: 3273 | J14: =I14/31 -> 105.58065 | K14: 4467 | L14: =K14/30 -> 148.9 | M14: 4764 | N14: =M14/31 -> 153.67742 | O14: 5061 | P14: =O14/30 -> 168.7 | Q14: 3473 | R14: =Q14/31 -> 112.03226 | S14: 4449 | T14: =S14/31 -> 143.51613 | U14: 3851 | V14: =U14/30 -> 128.36667 | W14: 4021 | X14: =W14/31 -> 129.70968 | Y14: 2884 | Z14: =Y14/30 -> 96.133333 | AA14: 2880 | AB14: =AA14/31 -> 92.903226 | AC14: =SUM(E14:AA14) -> 46102.153 | AD14: =IFERROR(STDEV(F14,H14,J14,L14,N14,P14,R14,T14,V14,X14,Z14,AB14),0) -> 27.447935 | AE14: 3361 | AF14: =AE14/31 -> 108.41935 | AG14: 2208 | AH14: =AG14/28 -> 78.857143 | AI14: 3078 | AJ14: =AI14/31 -> 99.290323 | AK14: 4051 | AL14: =AK14/30 -> 135.03333 | AM14: 3272 | AN14: =AM14/31 -> 105.54839 | AO14: 2593 | AP14: =AO14/30 -> 86.433333 | AQ14: 3450 | AR14: =AQ14/31 -> 111.29032 | AS14: 2487 | AT14: =AS14/31 -> 80.225806 | AU14: 3889 | AV14: =AU14/30 -> 129.63333 | AW14: 2202 | AX14: =AW14/31 -> 71.032258 | AY14: 3242 | AZ14: =AY14/30 -> 108.06667 | BA14: 3725 | BB14: =BA14/31 -> 120.16129 | BC14: =SUM(AE14:BA14) -> 38671.83 | BD14: =IFERROR(STDEV(AF14,AH14,AJ14,AL14,AN14,AP14,AR14,AT14,AV14,AX14,AZ14,BB14),0) -> 20.386272 | BE14: 2459 | BF14: =BE14/31 -> 79.322581 | BG14: 4406 | BH14: =BG14/28 -> 157.35714 | BI14: 2802 | BJ14: =BI14/31 -> 90.387097 | BK14: 3834 | BL14: =BK14/30 -> 127.8 | BM14: 2532 | BN14: =BM14/31 -> 81.677419 | BO14: 3572 | BP14: =BO14/30 -> 119.06667 | BQ14: 3043 | BR14: =BQ14/31 -> 98.16129 | BS14: 3407 | BT14: =BS14/31 -> 109.90323 | BU14: 4781 | BV14: =BU14/30 -> 159.36667 | BW14: 3572 | BX14: =BW14/31 -> 115.22581 | BY14: 4752 | BZ14: =BY14/30 -> 158.4 | CA14: 5005 | CB14: =CA14/31 -> 161.45161 | CC14: =SUM(BE14:CA14) -> 45461.668 | CD14: =IFERROR(STDEV(BF14,BH14,BJ14,BL14,BN14,BP14,BR14,BT14,BV14,BX14,BZ14,CB14),0) -> 31.296677 | CE14: 3070 | CF14: =CE14/31 -> 99.032258 | CG14: 2548 | CH14: =CG14/28 -> 91 | CI14: 2357 | CJ14: =CI14/31 -> 76.032258 | CK14: 3949 | CL14: =CK14/30 -> 131.63333 | CM14: 5360 | CN14: =CM14/31 -> 172.90323 | CO14: 3369 | CP14: =CO14/30 -> 112.3 | CQ14: 4288 | CR14: =CQ14/31 -> 138.32258 | CS14: 4690 | CT14: =CS14/31 -> 151.29032 | CU14: 4293 | CV14: =CU14/30 -> 143.1 | CW14: 4607 | CX14: =CW14/31 -> 148.6129 | CY14: 5206 | CZ14: =CY14/30 -> 173.53333 | DA14: 2908 | DB14: =DA14/31 -> 93.806452 | DC14: =SUM(CE14:DA14) -> 48082.76 | DD14: =IFERROR(STDEV(CF14,CH14,CJ14,CL14,CN14,CP14,CR14,CT14,CV14,CX14,CZ14,DB14),0) -> 32.651756 | DE14: 2341 | DF14: =DE14/31 -> 75.516129 | DG14: 2743 | DH14: =DG14/28 -> 97.964286 | DI14: 2663 | DJ14: =DI14/31 -> 85.903226 | DK14: 4314 | DL14: =DK14/30 -> 143.8 | DM14: 3994 | DN14: =DM14/31 -> 128.83871 | DO14: 2942 | DP14: =DO14/30 -> 98.066667 | DQ14: 4405 | DR14: =DQ14/31 -> 142.09677 | DS14: 4610 | DT14: =DS14/31 -> 148.70968 | DU14: 2789 | DV14: =DU14/30 -> 92.966667 | DW14: 4125 | DX14: =DW14/31 -> 133.06452 | DY14: 4553 | DZ14: =DY14/30 -> 151.76667 | EA14: 2628 | EB14: =EA14/31 -> 84.774194 | EC14: =SUM(DE14:EA14) -> 43405.693 | ED14: =IFERROR(STDEV(DF14,DH14,DJ14,DL14,DN14,DP14,DR14,DT14,DV14,DX14,DZ14,EB14),0) -> 28.524724 | EE14: =STDEV(F14:AB14,AF14:BB14,BF14:CB14,CF14:DB14,DF14:EB14) -> 1871.7959
A15: 10 | B15: BB010 | C15: Talc Powder | D15: kg | E15: 3941 | F15: =E15/31 -> 127.12903 | G15: 4307 | H15: =G15/28 -> 153.82143 | I15: 2155 | J15: =I15/31 -> 69.516129 | K15: 1948 | L15: =K15/30 -> 64.933333 | M15: 2667 | N15: =M15/31 -> 86.032258 | O15: 3585 | P15: =O15/30 -> 119.5 | Q15: 4290 | R15: =Q15/31 -> 138.3871 | S15: 2880 | T15: =S15/31 -> 92.903226 | U15: 3680 | V15: =U15/30 -> 122.66667 | W15: 2075 | X15: =W15/31 -> 66.935484 | Y15: 3618 | Z15: =Y15/30 -> 120.6 | AA15: 3459 | AB15: =AA15/31 -> 111.58065 | AC15: =SUM(E15:AA15) -> 39767.425 | AD15: =IFERROR(STDEV(F15,H15,J15,L15,N15,P15,R15,T15,V15,X15,Z15,AB15),0) -> 29.542053 | AE15: 1946 | AF15: =AE15/31 -> 62.774194 | AG15: 3478 | AH15: =AG15/28 -> 124.21429 | AI15: 3656 | AJ15: =AI15/31 -> 117.93548 | AK15: 3085 | AL15: =AK15/30 -> 102.83333 | AM15: 1990 | AN15: =AM15/31 -> 64.193548 | AO15: 3961 | AP15: =AO15/30 -> 132.03333 | AQ15: 3501 | AR15: =AQ15/31 -> 112.93548 | AS15: 2506 | AT15: =AS15/31 -> 80.83871 | AU15: 2692 | AV15: =AU15/30 -> 89.733333 | AW15: 2560 | AX15: =AW15/31 -> 82.580645 | AY15: 2869 | AZ15: =AY15/30 -> 95.633333 | BA15: 2493 | BB15: =BA15/31 -> 80.419355 | BC15: =SUM(AE15:BA15) -> 35802.706 | BD15: =IFERROR(STDEV(AF15,AH15,AJ15,AL15,AN15,AP15,AR15,AT15,AV15,AX15,AZ15,BB15),0) -> 22.791449 | BE15: 3099 | BF15: =BE15/31 -> 99.967742 | BG15: 3046 | BH15: =BG15/28 -> 108.78571 | BI15: 1657 | BJ15: =BI15/31 -> 53.451613 | BK15: 3314 | BL15: =BK15/30 -> 110.46667 | BM15: 2684 | BN15: =BM15/31 -> 86.580645 | BO15: 3058 | BP15: =BO15/30 -> 101.93333 | BQ15: 2823 | BR15: =BQ15/31 -> 91.064516 | BS15: 2296 | BT15: =BS15/31 -> 74.064516 | BU15: 2874 | BV15: =BU15/30 -> 95.8 | BW15: 3323 | BX15: =BW15/31 -> 107.19355 | BY15: 1976 | BZ15: =BY15/30 -> 65.866667 | CA15: 3019 | CB15: =CA15/31 -> 97.387097 | CC15: =SUM(BE15:CA15) -> 34164.175 | CD15: =IFERROR(STDEV(BF15,BH15,BJ15,BL15,BN15,BP15,BR15,BT15,BV15,BX15,BZ15,CB15),0) -> 18.013106 | CE15: 3313 | CF15: =CE15/31 -> 106.87097 | CG15: 3173 | CH15: =CG15/28 -> 113.32143 | CI15: 3049 | CJ15: =CI15/31 -> 98.354839 | CK15: 3809 | CL15: =CK15/30 -> 126.96667 | CM15: 2619 | CN15: =CM15/31 -> 84.483871 | CO15: 4120 | CP15: =CO15/30 -> 137.33333 | CQ15: 4066 | CR15: =CQ15/31 -> 131.16129 | CS15: 2152 | CT15: =CS15/31 -> 69.419355 | CU15: 4197 | CV15: =CU15/30 -> 139.9 | CW15: 2556 | CX15: =CW15/31 -> 82.451613 | CY15: 3124 | CZ15: =CY15/30 -> 104.13333 | DA15: 3499 | DB15: =DA15/31 -> 112.87097 | DC15: =SUM(CE15:DA15) -> 40871.397 | DD15: =IFERROR(STDEV(CF15,CH15,CJ15,CL15,CN15,CP15,CR15,CT15,CV15,CX15,CZ15,DB15),0) -> 22.601584 | DE15: 2252 | DF15: =DE15/31 -> 72.645161 | DG15: 1553 | DH15: =DG15/28 -> 55.464286 | DI15: 3193 | DJ15: =DI15/31 -> 103 | DK15: 1859 | DL15: =DK15/30 -> 61.966667 | DM15: 1919 | DN15: =DM15/31 -> 61.903226 | DO15: 3087 | DP15: =DO15/30 -> 102.9 | DQ15: 2175 | DR15: =DQ15/31 -> 70.16129 | DS15: 3252 | DT15: =DS15/31 -> 104.90323 | DU15: 2895 | DV15: =DU15/30 -> 96.5 | DW15: 2047 | DX15: =DW15/31 -> 66.032258 | DY15: 1516 | DZ15: =DY15/30 -> 50.533333 | EA15: 3387 | EB15: =EA15/31 -> 109.25806 | EC15: =SUM(DE15:EA15) -> 29981.009 | ED15: =IFERROR(STDEV(DF15,DH15,DJ15,DL15,DN15,DP15,DR15,DT15,DV15,DX15,DZ15,EB15),0) -> 21.886007 | EE15: =STDEV(F15:AB15,AF15:BB15,BF15:CB15,CF15:DB15,DF15:EB15) -> 1505.6254
A16: 11 | B16: BB011 | C16: Aqua DM | D16: L | E16: 488 | F16: =E16/31 -> 15.741935 | G16: 859 | H16: =G16/28 -> 30.678571 | I16: 724 | J16: =I16/31 -> 23.354839 | K16: 881 | L16: =K16/30 -> 29.366667 | M16: 842 | N16: =M16/31 -> 27.16129 | O16: 816 | P16: =O16/30 -> 27.2 | Q16: 725 | R16: =Q16/31 -> 23.387097 | S16: 902 | T16: =S16/31 -> 29.096774 | U16: 493 | V16: =U16/30 -> 16.433333 | W16: 568 | X16: =W16/31 -> 18.322581 | Y16: 843 | Z16: =Y16/30 -> 28.1 | AA16: 617 | AB16: =AA16/31 -> 19.903226 | AC16: =SUM(E16:AA16) -> 9026.8431 | AD16: =IFERROR(STDEV(F16,H16,J16,L16,N16,P16,R16,T16,V16,X16,Z16,AB16),0) -> 5.3226573 | AE16: 760 | AF16: =AE16/31 -> 24.516129 | AG16: 698 | AH16: =AG16/28 -> 24.928571 | AI16: 731 | AJ16: =AI16/31 -> 23.580645 | AK16: 671 | AL16: =AK16/30 -> 22.366667 | AM16: 854 | AN16: =AM16/31 -> 27.548387 | AO16: 617 | AP16: =AO16/30 -> 20.566667 | AQ16: 829 | AR16: =AQ16/31 -> 26.741935 | AS16: 583 | AT16: =AS16/31 -> 18.806452 | AU16: 572 | AV16: =AU16/30 -> 19.066667 | AW16: 497 | AX16: =AW16/31 -> 16.032258 | AY16: 538 | AZ16: =AY16/30 -> 17.933333 | BA16: 496 | BB16: =BA16/31 -> 16 | BC16: =SUM(AE16:BA16) -> 8088.0877 | BD16: =IFERROR(STDEV(AF16,AH16,AJ16,AL16,AN16,AP16,AR16,AT16,AV16,AX16,AZ16,BB16),0) -> 4.010297 | BE16: 852 | BF16: =BE16/31 -> 27.483871 | BG16: 1002 | BH16: =BG16/28 -> 35.785714 | BI16: 620 | BJ16: =BI16/31 -> 20 | BK16: 640 | BL16: =BK16/30 -> 21.333333 | BM16: 818 | BN16: =BM16/31 -> 26.387097 | BO16: 977 | BP16: =BO16/30 -> 32.566667 | BQ16: 1144 | BR16: =BQ16/31 -> 36.903226 | BS16: 845 | BT16: =BS16/31 -> 27.258065 | BU16: 684 | BV16: =BU16/30 -> 22.8 | BW16: 564 | BX16: =BW16/31 -> 18.193548 | BY16: 626 | BZ16: =BY16/30 -> 20.866667 | CA16: 648 | CB16: =CA16/31 -> 20.903226 | CC16: =SUM(BE16:CA16) -> 9709.5782 | CD16: =IFERROR(STDEV(BF16,BH16,BJ16,BL16,BN16,BP16,BR16,BT16,BV16,BX16,BZ16,CB16),0) -> 6.3445796 | CE16: 566 | CF16: =CE16/31 -> 18.258065 | CG16: 465 | CH16: =CG16/28 -> 16.607143 | CI16: 782 | CJ16: =CI16/31 -> 25.225806 | CK16: 624 | CL16: =CK16/30 -> 20.8 | CM16: 1050 | CN16: =CM16/31 -> 33.870968 | CO16: 794 | CP16: =CO16/30 -> 26.466667 | CQ16: 882 | CR16: =CQ16/31 -> 28.451613 | CS16: 534 | CT16: =CS16/31 -> 17.225806 | CU16: 986 | CV16: =CU16/30 -> 32.866667 | CW16: 756 | CX16: =CW16/31 -> 24.387097 | CY16: 988 | CZ16: =CY16/30 -> 32.933333 | DA16: 806 | DB16: =DA16/31 -> 26 | DC16: =SUM(CE16:DA16) -> 9510.0932 | DD16: =IFERROR(STDEV(CF16,CH16,CJ16,CL16,CN16,CP16,CR16,CT16,CV16,CX16,CZ16,DB16),0) -> 6.121365 | DE16: 846 | DF16: =DE16/31 -> 27.290323 | DG16: 826 | DH16: =DG16/28 -> 29.5 | DI16: 648 | DJ16: =DI16/31 -> 20.903226 | DK16: 556 | DL16: =DK16/30 -> 18.533333 | DM16: 1173 | DN16: =DM16/31 -> 37.83871 | DO16: 852 | DP16: =DO16/30 -> 28.4 | DQ16: 1091 | DR16: =DQ16/31 -> 35.193548 | DS16: 798 | DT16: =DS16/31 -> 25.741935 | DU16: 572 | DV16: =DU16/30 -> 19.066667 | DW16: 957 | DX16: =DW16/31 -> 30.870968 | DY16: 558 | DZ16: =DY16/30 -> 18.6 | EA16: 624 | EB16: =EA16/31 -> 20.129032 | EC16: =SUM(DE16:EA16) -> 9792.9387 | ED16: =IFERROR(STDEV(DF16,DH16,DJ16,DL16,DN16,DP16,DR16,DT16,DV16,DX16,DZ16,EB16),0) -> 6.6549465 | EE16: =STDEV(F16:AB16,AF16:BB16,BF16:CB16,CF16:DB16,DF16:EB16) -> 383.95902
A17: 12 | B17: BB012 | C17: Zinc Oxide | D17: kg | E17: 986 | F17: =E17/31 -> 31.806452 | G17: 791 | H17: =G17/28 -> 28.25 | I17: 1310 | J17: =I17/31 -> 42.258065 | K17: 652 | L17: =K17/30 -> 21.733333 | M17: 1137 | N17: =M17/31 -> 36.677419 | O17: 1018 | P17: =O17/30 -> 33.933333 | Q17: 1157 | R17: =Q17/31 -> 37.322581 | S17: 733 | T17: =S17/31 -> 23.645161 | U17: 956 | V17: =U17/30 -> 31.866667 | W17: 901 | X17: =W17/31 -> 29.064516 | Y17: 896 | Z17: =Y17/30 -> 29.866667 | AA17: 1209 | AB17: =AA17/31 -> 39 | AC17: =SUM(E17:AA17) -> 12092.424 | AD17: =IFERROR(STDEV(F17,H17,J17,L17,N17,P17,R17,T17,V17,X17,Z17,AB17),0) -> 6.1088494 | AE17: 1339 | AF17: =AE17/31 -> 43.193548 | AG17: 812 | AH17: =AG17/28 -> 29 | AI17: 1055 | AJ17: =AI17/31 -> 34.032258 | AK17: 1047 | AL17: =AK17/30 -> 34.9 | AM17: 1147 | AN17: =AM17/31 -> 37 | AO17: 1307 | AP17: =AO17/30 -> 43.566667 | AQ17: 737 | AR17: =AQ17/31 -> 23.774194 | AS17: 740 | AT17: =AS17/31 -> 23.870968 | AU17: 1086 | AV17: =AU17/30 -> 36.2 | AW17: 698 | AX17: =AW17/31 -> 22.516129 | AY17: 711 | AZ17: =AY17/30 -> 23.7 | BA17: 635 | BB17: =BA17/31 -> 20.483871 | BC17: =SUM(AE17:BA17) -> 11665.754 | BD17: =IFERROR(STDEV(AF17,AH17,AJ17,AL17,AN17,AP17,AR17,AT17,AV17,AX17,AZ17,BB17),0) -> 8.1849864 | BE17: 480 | BF17: =BE17/31 -> 15.483871 | BG17: 765 | BH17: =BG17/28 -> 27.321429 | BI17: 856 | BJ17: =BI17/31 -> 27.612903 | BK17: 663 | BL17: =BK17/30 -> 22.1 | BM17: 625 | BN17: =BM17/31 -> 20.16129 | BO17: 928 | BP17: =BO17/30 -> 30.933333 | BQ17: 926 | BR17: =BQ17/31 -> 29.870968 | BS17: 767 | BT17: =BS17/31 -> 24.741935 | BU17: 916 | BV17: =BU17/30 -> 30.533333 | BW17: 1066 | BX17: =BW17/31 -> 34.387097 | BY17: 980 | BZ17: =BY17/30 -> 32.666667 | CA17: 876 | CB17: =CA17/31 -> 28.258065 | CC17: =SUM(BE17:CA17) -> 10143.813 | CD17: =IFERROR(STDEV(BF17,BH17,BJ17,BL17,BN17,BP17,BR17,BT17,BV17,BX17,BZ17,CB17),0) -> 5.5056799 | CE17: 949 | CF17: =CE17/31 -> 30.612903 | CG17: 1132 | CH17: =CG17/28 -> 40.428571 | CI17: 790 | CJ17: =CI17/31 -> 25.483871 | CK17: 871 | CL17: =CK17/30 -> 29.033333 | CM17: 940 | CN17: =CM17/31 -> 30.322581 | CO17: 1115 | CP17: =CO17/30 -> 37.166667 | CQ17: 1060 | CR17: =CQ17/31 -> 34.193548 | CS17: 552 | CT17: =CS17/31 -> 17.806452 | CU17: 616 | CV17: =CU17/30 -> 20.533333 | CW17: 711 | CX17: =CW17/31 -> 22.935484 | CY17: 1008 | CZ17: =CY17/30 -> 33.6 | DA17: 887 | DB17: =DA17/31 -> 28.612903 | DC17: =SUM(CE17:DA17) -> 10953.117 | DD17: =IFERROR(STDEV(CF17,CH17,CJ17,CL17,CN17,CP17,CR17,CT17,CV17,CX17,CZ17,DB17),0) -> 6.7111972 | DE17: 832 | DF17: =DE17/31 -> 26.83871 | DG17: 701 | DH17: =DG17/28 -> 25.035714 | DI17: 1153 | DJ17: =DI17/31 -> 37.193548 | DK17: 1161 | DL17: =DK17/30 -> 38.7 | DM17: 1356 | DN17: =DM17/31 -> 43.741935 | DO17: 1002 | DP17: =DO17/30 -> 33.4 | DQ17: 997 | DR17: =DQ17/31 -> 32.16129 | DS17: 665 | DT17: =DS17/31 -> 21.451613 | DU17: 633 | DV17: =DU17/30 -> 21.1 | DW17: 947 | DX17: =DW17/31 -> 30.548387 | DY17: 859 | DZ17: =DY17/30 -> 28.633333 | EA17: 801 | EB17: =EA17/31 -> 25.83871 | EC17: =SUM(DE17:EA17) -> 11445.805 | ED17: =IFERROR(STDEV(DF17,DH17,DJ17,DL17,DN17,DP17,DR17,DT17,DV17,DX17,DZ17,EB17),0) -> 6.9877823 | EE17: =STDEV(F17:AB17,AF17:BB17,BF17:CB17,CF17:DB17,DF17:EB17) -> 462.48101
... A105: 100 | B105: BB100 | C105: Titanium Dioxide Anatase | D105: kg | E105: 2890 | F105: =E105/31 -> 93.225806 | G105: 1807 | H105: =G105/28 -> 64.535714 | I105: 2070 | J105: =I105/31 -> 66.774194 | K105: 2646 | L105: =K105/30 -> 88.2 | M105: 3495 | N105: =M105/31 -> 112.74194 | O105: 3753 | P105: =O105/30 -> 125.1 | Q105: 1764 | R105: =Q105/31 -> 56.903226 | S105: 3695 | T105: =S105/31 -> 119.19355 | U105: 3255 | V105: =U105/30 -> 108.5 | W105: 1812 | X105: =W105/31 -> 58.451613 | Y105: 2506 | Z105: =Y105/30 -> 83.533333 | AA105: 3597 | AB105: =AA105/31 -> 116.03226 | AC105: =SUM(E105:AA105) -> 34267.159 | AD105: =IFERROR(STDEV(F105,H105,J105,L105,N105,P105,R105,T105,V105,X105,Z105,AB105),0) -> 25.119577 | AE105: 2627 | AF105: =AE105/31 -> 84.741935 | AG105: 2945 | AH105: =AG105/28 -> 105.17857 | AI105: 3294 | AJ105: =AI105/31 -> 106.25806 | AK105: 3395 | AL105: =AK105/30 -> 113.16667 | AM105: 2001 | AN105: =AM105/31 -> 64.548387 | AO105: 2111 | AP105: =AO105/30 -> 70.366667 | AQ105: 2553 | AR105: =AQ105/31 -> 82.354839 | AS105: 2941 | AT105: =AS105/31 -> 94.870968 | AU105: 1787 | AV105: =AU105/30 -> 59.566667 | AW105: 3555 | AX105: =AW105/31 -> 114.67742 | AY105: 3574 | AZ105: =AY105/30 -> 119.13333 | BA105: 2377 | BB105: =BA105/31 -> 76.677419 | BC105: =SUM(AE105:BA105) -> 34174.864 | BD105: =IFERROR(STDEV(AF105,AH105,AJ105,AL105,AN105,AP105,AR105,AT105,AV105,AX105,AZ105,BB105),0) -> 20.725014 | BE105: 2342 | BF105: =BE105/31 -> 75.548387 | BG105: 2171 | BH105: =BG105/28 -> 77.535714 | BI105: 1390 | BJ105: =BI105/31 -> 44.83871 | BK105: 1346 | BL105: =BK105/30 -> 44.866667 | BM105: 1812 | BN105: =BM105/31 -> 58.451613 | BO105: 3052 | BP105: =BO105/30 -> 101.73333 | BQ105: 2834 | BR105: =BQ105/31 -> 91.419355 | BS105: 2187 | BT105: =BS105/31 -> 70.548387 | BU105: 2511 | BV105: =BU105/30 -> 83.7 | BW105: 2939 | BX105: =BW105/31 -> 94.806452 | BY105: 2088 | BZ105: =BY105/30 -> 69.6 | CA105: 2222 | CB105: =CA105/31 -> 71.677419 | CC105: =SUM(BE105:CA105) -> 27707.049 | CD105: =IFERROR(STDEV(BF105,BH105,BJ105,BL105,BN105,BP105,BR105,BT105,BV105,BX105,BZ105,CB105),0) -> 18.068375 | CE105: 2544 | CF105: =CE105/31 -> 82.064516 | CG105: 1760 | CH105: =CG105/28 -> 62.857143 | CI105: 1538 | CJ105: =CI105/31 -> 49.612903 | CK105: 1817 | CL105: =CK105/30 -> 60.566667 | CM105: 3086 | CN105: =CM105/31 -> 99.548387 | CO105: 1445 | CP105: =CO105/30 -> 48.166667 | CQ105: 2646 | CR105: =CQ105/31 -> 85.354839 | CS105: 2355 | CT105: =CS105/31 -> 75.967742 | CU105: 2327 | CV105: =CU105/30 -> 77.566667 | CW105: 2863 | CX105: =CW105/31 -> 92.354839 | CY105: 2438 | CZ105: =CY105/30 -> 81.266667 | DA105: 2169 | DB105: =DA105/31 -> 69.967742 | DC105: =SUM(CE105:DA105) -> 27803.327 | DD105: =IFERROR(STDEV(CF105,CH105,CJ105,CL105,CN105,CP105,CR105,CT105,CV105,CX105,CZ105,DB105),0) -> 16.054864 | DE105: 3500 | DF105: =DE105/31 -> 112.90323 | DG105: 2107 | DH105: =DG105/28 -> 75.25 | DI105: 3060 | DJ105: =DI105/31 -> 98.709677 | DK105: 3212 | DL105: =DK105/30 -> 107.06667 | DM105: 3866 | DN105: =DM105/31 -> 124.70968 | DO105: 2212 | DP105: =DO105/30 -> 73.733333 | DQ105: 1959 | DR105: =DQ105/31 -> 63.193548 | DS105: 2592 | DT105: =DS105/31 -> 83.612903 | DU105: 3946 | DV105: =DU105/30 -> 131.53333 | DW105: 2146 | DX105: =DW105/31 -> 69.225806 | DY105: 2213 | DZ105: =DY105/30 -> 73.766667 | EA105: 2478 | EB105: =EA105/31 -> 79.935484 | EC105: =SUM(DE105:EA105) -> 34304.705 | ED105: =IFERROR(STDEV(DF105,DH105,DJ105,DL105,DN105,DP105,DR105,DT105,DV105,DX105,DZ105,EB105),0) -> 23.049142 | EE105: =STDEV(F105:AB105,AF105:BB105,BF105:CB105,CF105:DB105,DF105:EB105) -> 1320.8107

Sheet Data Historis 5 Tahun
A1: DATA HISTORIS BAHAN BAKU 5 TAHUN (2021–2025) — PT. JJ Top Cosmindo Sidoarjo
A2: D = total tahunan dari Data Bulanan | d = rata-rata d_harian 12 bulan dari Data Bulanan | σ_d = STDEV(12 d_harian tahun tsb.) dari Data Bulanan | SS = 1.65 × σ_d × √LT
A3: EOQ = √(2DS/H) | σ_DL = σ_d × √LT | SS = 1.65 × σ_DL | ROP = d × LT + SS | Slope = SUMPRODUCT({-2,-1,0,1,2}, D) / 10 | R² = Slope² × 10 / (ΣD² − (ΣD)²/5)
A4: 🟡 Kuning = data input/referensi Bulanan | 🟢 Hijau = formula EOQ | 🟠 Oranye = formula SS | 🟣 Ungu = formula ROP | 🔵 Biru = analisis trend
A5: DATA IDENTITAS & INPUT AKTUAL (D, d, σ_d dari Data Bulanan) | I5: PERHITUNGAN EOQ | M5: PERHITUNGAN σ_DL & SAFETY STOCK (SS) Z = 1.65 (Service Level 95%) | Q5: PERHITUNGAN ROP & STATUS | T5: ANALISIS TREND & FLUKTUATIF
A6: No | B6: Tahun | C6: Kategori | D6: Kode | E6: Nama Bahan Baku | F6: Satuan | G6: Stok Aktual (unit) | H6: LT Lead Time (hari) | I6: (D) Permintaan Tahunan (unit/thn) | J6: (S) Biaya Pemesanan (Rp/order) | K6: (H) Biaya Simpan (Rp/unit/thn) | L6: EOQ = √(2×D×S/H) | M6: (d) Permintaan Harian (unit/hr) | N6: σ_d per Tahun (Std Dev 12 d_harian) | O6: σ_DL = σ_d × √LT | P6: SS (SL 95%) = 1.65 × σ_DL | Q6: ROP = d × LT + SS | R6: Selisih (Stok − ROP) | S6: STATUS | T6: CV = σ_d / d̄ | U6: Slope Trend (unit/thn) | V6: R² Trend
A7: 1 | B7: 2021 | C7: Lokal | D7: BB001 | E7: Phenoxyethanol | F7: kg | G7: 0 | H7: 6 | I7: =IFERROR(ROUND('Data Bulanan'!AC6,0),0) -> 37912 | J7: 2168498 | K7: 87265 | L7: =IFERROR(ROUND(SQRT(2*I7*J7/K7),0),0) -> 1373 | M7: =IFERROR(AVERAGE('Data Bulanan'!F6,'Data Bulanan'!H6,'Data Bulanan'!J6,'Data Bulanan'!L6,'Data Bulanan'!N6,'Data Bulanan'!P6,'Data Bulanan'!R6,'Data Bulanan'!T6,'Data Bulanan'!V6,'Data Bulanan'!X6,'Data Bulanan'!Z6,'Data Bulanan'!AB6),0) -> 100.64895 | N7: ='Data Bulanan'!AD6 -> 24.865922 | O7: =IFERROR(N7*SQRT(H7),0) -> 60.90882 | P7: =IFERROR(ROUND(1.65*O7,0),0) -> 100 | Q7: =IFERROR(ROUND(M7*H7+P7,0),0) -> 704 | R7: =G7-Q7 -> -704 | S7: =IF(G7=0,"Stockout ⚠",IF(G7<Q7,"Reorder 🔄",IF(G7>Q7+L7,"Overstock 📦","Aman ✅"))) -> Stockout ⚠ | T7: =IFERROR(N7/AVERAGE(M7:M11),0) -> 0.25176057 | U7: -826.12 | V7: 0.1498
A8: 2 | B8: 2022 | C8: Lokal | D8: BB001 | E8: Phenoxyethanol | F8: kg | G8: 611 | H8: 6 | I8: =IFERROR(ROUND('Data Bulanan'!BC6,0),0) -> 36654 | J8: 2246093 | K8: 88264 | L8: =IFERROR(ROUND(SQRT(2*I8*J8/K8),0),0) -> 1366 | M8: =IFERROR(AVERAGE('Data Bulanan'!AF6,'Data Bulanan'!AH6,'Data Bulanan'!AJ6,'Data Bulanan'!AL6,'Data Bulanan'!AN6,'Data Bulanan'!AP6,'Data Bulanan'!AR6,'Data Bulanan'!AT6,'Data Bulanan'!AV6,'Data Bulanan'!AX6,'Data Bulanan'!AZ6,'Data Bulanan'!BB6),0) -> 97.475691 | N8: ='Data Bulanan'!BD6 -> 24.53334 | O8: =IFERROR(N8*SQRT(H8),0) -> 60.094164 | P8: =IFERROR(ROUND(1.65*O8,0),0) -> 99 | Q8: =IFERROR(ROUND(M8*H8+P8,0),0) -> 684 | R8: =G8-Q8 -> -73 | S8: =IF(G8=0,"Stockout ⚠",IF(G8<Q8,"Reorder 🔄",IF(G8>Q8+L8,"Overstock 📦","Aman ✅"))) -> Reorder 🔄 | T8: =IFERROR(N8/AVERAGE(M7:M11),0) -> 0.24839327 | U8: -826.12 | V8: 0.1498
A9: 3 | B9: 2023 | C9: Lokal | D9: BB001 | E9: Phenoxyethanol | F9: kg | G9: 5530 | H9: 6 | I9: =IFERROR(ROUND('Data Bulanan'!CC6,0),0) -> 38822 | J9: 2073806 | K9: 84691 | L9: =IFERROR(ROUND(SQRT(2*I9*J9/K9),0),0) -> 1379 | M9: =IFERROR(AVERAGE('Data Bulanan'!BF6,'Data Bulanan'!BH6,'Data Bulanan'!BJ6,'Data Bulanan'!BL6,'Data Bulanan'!BN6,'Data Bulanan'!BP6,'Data Bulanan'!BR6,'Data Bulanan'!BT6,'Data Bulanan'!BV6,'Data Bulanan'!BX6,'Data Bulanan'!BZ6,'Data Bulanan'!CB6),0) -> 103.02451 | N9: ='Data Bulanan'!CD6 -> 22.230843 | O9: =IFERROR(N9*SQRT(H9),0) -> 54.454222 | P9: =IFERROR(ROUND(1.65*O9,0),0) -> 90 | Q9: =IFERROR(ROUND(M9*H9+P9,0),0) -> 708 | R9: =G9-Q9 -> 4822 | S9: =IF(G9=0,"Stockout ⚠",IF(G9<Q9,"Reorder 🔄",IF(G9>Q9+L9,"Overstock 📦","Aman ✅"))) -> Overstock 📦 | T9: =IFERROR(N9/AVERAGE(M7:M11),0) -> 0.22508113 | U9: -826.12 | V9: 0.1498
A10: 4 | B10: 2024 | C10: Lokal | D10: BB001 | E10: Phenoxyethanol | F10: kg | G10: 0 | H10: 6 | I10: =IFERROR(ROUND('Data Bulanan'!DC6,0),0) -> 40721 | J10: 2187510 | K10: 76011 | L10: =IFERROR(ROUND(SQRT(2*I10*J10/K10),0),0) -> 1531 | M10: =IFERROR(AVERAGE('Data Bulanan'!CF6,'Data Bulanan'!CH6,'Data Bulanan'!CJ6,'Data Bulanan'!CL6,'Data Bulanan'!CN6,'Data Bulanan'!CP6,'Data Bulanan'!CR6,'Data Bulanan'!CT6,'Data Bulanan'!CV6,'Data Bulanan'!CX6,'Data Bulanan'!CZ6,'Data Bulanan'!DB6),0) -> 108.32357 | N10: ='Data Bulanan'!DD6 -> 27.966488 | O10: =IFERROR(N10*SQRT(H10),0) -> 68.503625 | P10: =IFERROR(ROUND(1.65*O10,0),0) -> 113 | Q10: =IFERROR(ROUND(M10*H10+P10,0),0) -> 763 | R10: =G10-Q10 -> -763 | S10: =IF(G10=0,"Stockout ⚠",IF(G10<Q10,"Reorder 🔄",IF(G10>Q10+L10,"Overstock 📦","Aman ✅"))) -> Stockout ⚠ | T10: =IFERROR(N10/AVERAGE(M7:M11),0) -> 0.28315295 | U10: -826.12 | V10: 0.1498
A11: 5 | B11: 2025 | C11: Lokal | D11: BB001 | E11: Phenoxyethanol | F11: kg | G11: 4121 | H11: 6 | I11: =IFERROR(ROUND('Data Bulanan'!EC6,0),0) -> 31748 | J11: 2141357 | K11: 84902 | L11: =IFERROR(ROUND(SQRT(2*I11*J11/K11),0),0) -> 1265 | M11: =IFERROR(AVERAGE('Data Bulanan'!DF6,'Data Bulanan'!DH6,'Data Bulanan'!DJ6,'Data Bulanan'!DL6,'Data Bulanan'!DN6,'Data Bulanan'!DP6,'Data Bulanan'!DR6,'Data Bulanan'!DT6,'Data Bulanan'!DV6,'Data Bulanan'!DX6,'Data Bulanan'!DZ6,'Data Bulanan'!EB6),0) -> 84.367947 | N11: ='Data Bulanan'!ED6 -> 17.037135 | O11: =IFERROR(N11*SQRT(H11),0) -> 41.732287 | P11: =IFERROR(ROUND(1.65*O11,0),0) -> 69 | Q11: =IFERROR(ROUND(M11*H11+P11,0),0) -> 575 | R11: =G11-Q11 -> 3546 | S11: =IF(G11=0,"Stockout ⚠",IF(G11<Q11,"Reorder 🔄",IF(G11>Q11+L11,"Overstock 📦","Aman ✅"))) -> Overstock 📦 | T11: =IFERROR(N11/AVERAGE(M7:M11),0) -> 0.17249627 | U11: -826.12 | V11: 0.1498
A12: 1 | B12: 2021 | C12: Lokal | D12: BB002 | E12: Glycerin | F12: kg | G12: 15322 | H12: 41 | I12: =IFERROR(ROUND('Data Bulanan'!AC7,0),0) -> 40423 | J12: 10459221 | K12: 103961 | L12: =IFERROR(ROUND(SQRT(2*I12*J12/K12),0),0) -> 2852 | M12: =IFERROR(AVERAGE('Data Bulanan'!F7,'Data Bulanan'!H7,'Data Bulanan'!J7,'Data Bulanan'!L7,'Data Bulanan'!N7,'Data Bulanan'!P7,'Data Bulanan'!R7,'Data Bulanan'!T7,'Data Bulanan'!V7,'Data Bulanan'!X7,'Data Bulanan'!Z7,'Data Bulanan'!AB7),0) -> 107.70978 | N12: ='Data Bulanan'!AD7 -> 26.809131 | O12: =IFERROR(N12*SQRT(H12),0) -> 171.6622 | P12: =IFERROR(ROUND(1.65*O12,0),0) -> 283 | Q12: =IFERROR(ROUND(M12*H12+P12,0),0) -> 4699 | R12: =G12-Q12 -> 10623 | S12: =IF(G12=0,"Stockout ⚠",IF(G12<Q12,"Reorder 🔄",IF(G12>Q12+L12,"Overstock 📦","Aman ✅"))) -> Overstock 📦 | T12: =IFERROR(N12/AVERAGE(M12:M16),0) -> 0.24972803 | U12: -2010.59 | V12: 0.428
A13: 2 | B13: 2022 | C13: Lokal | D13: BB002 | E13: Glycerin | F13: kg | G13: 6496 | H13: 41 | I13: =IFERROR(ROUND('Data Bulanan'!BC7,0),0) -> 45365 | J13: 10897733 | K13: 103809 | L13: =IFERROR(ROUND(SQRT(2*I13*J13/K13),0),0) -> 3086 | M13: =IFERROR(AVERAGE('Data Bulanan'!AF7,'Data Bulanan'!AH7,'Data Bulanan'!AJ7,'Data Bulanan'!AL7,'Data Bulanan'!AN7,'Data Bulanan'!AP7,'Data Bulanan'!AR7,'Data Bulanan'!AT7,'Data Bulanan'!AV7,'Data Bulanan'!AX7,'Data Bulanan'!AZ7,'Data Bulanan'!BB7),0) -> 120.62002 | N13: ='Data Bulanan'!BD7 -> 22.668063 | O13: =IFERROR(N13*SQRT(H13),0) -> 145.14642 | P13: =IFERROR(ROUND(1.65*O13,0),0) -> 239 | Q13: =IFERROR(ROUND(M13*H13+P13,0),0) -> 5184 | R13: =G13-Q13 -> 1312 | S13: =IF(G13=0,"Stockout ⚠",IF(G13<Q13,"Reorder 🔄",IF(G13>Q13+L13,"Overstock 📦","Aman ✅"))) -> Aman ✅ | T13: =IFERROR(N13/AVERAGE(M12:M16),0) -> 0.21115383 | U13: -2010.59 | V13: 0.428
A14: 3 | B14: 2023 | C14: Lokal | D14: BB002 | E14: Glycerin | F14: kg | G14: 16278 | H14: 41 | I14: =IFERROR(ROUND('Data Bulanan'!CC7,0),0) -> 45017 | J14: 10242342 | K14: 124568 | L14: =IFERROR(ROUND(SQRT(2*I14*J14/K14),0),0) -> 2721 | M14: =IFERROR(AVERAGE('Data Bulanan'!BF7,'Data Bulanan'!BH7,'Data Bulanan'!BJ7,'Data Bulanan'!BL7,'Data Bulanan'!BN7,'Data Bulanan'!BP7,'Data Bulanan'!BR7,'Data Bulanan'!BT7,'Data Bulanan'!BV7,'Data Bulanan'!BX7,'Data Bulanan'!BZ7,'Data Bulanan'!CB7),0) -> 119.62558 | N14: ='Data Bulanan'!CD7 -> 31.361782 | O14: =IFERROR(N14*SQRT(H14),0) -> 200.81339 | P14: =IFERROR(ROUND(1.65*O14,0),0) -> 331 | Q14: =IFERROR(ROUND(M14*H14+P14,0),0) -> 5236 | R14: =G14-Q14 -> 11042 | S14: =IF(G14=0,"Stockout ⚠",IF(G14<Q14,"Reorder 🔄",IF(G14>Q14+L14,"Overstock 📦","Aman ✅"))) -> Overstock 📦 | T14: =IFERROR(N14/AVERAGE(M12:M16),0) -> 0.29213614 | U14: -2010.59 | V14: 0.428
A15: 4 | B15: 2024 | C15: Lokal | D15: BB002 | E15: Glycerin | F15: kg | G15: 23217 | H15: 41 | I15: =IFERROR(ROUND('Data Bulanan'!DC7,0),0) -> 35851 | J15: 10188565 | K15: 116830 | L15: =IFERROR(ROUND(SQRT(2*I15*J15/K15),0),0) -> 2501 | M15: =IFERROR(AVERAGE('Data Bulanan'!CF7,'Data Bulanan'!CH7,'Data Bulanan'!CJ7,'Data Bulanan'!CL7,'Data Bulanan'!CN7,'Data Bulanan'!CP7,'Data Bulanan'!CR7,'Data Bulanan'!CT7,'Data Bulanan'!CV7,'Data Bulanan'!CX7,'Data Bulanan'!CZ7,'Data Bulanan'!DB7),0) -> 95.321051 | N15: ='Data Bulanan'!DD7 -> 22.635774 | O15: =IFERROR(N15*SQRT(H15),0) -> 144.93967 | P15: =IFERROR(ROUND(1.65*O15,0),0) -> 239 | Q15: =IFERROR(ROUND(M15*H15+P15,0),0) -> 4147 | R15: =G15-Q15 -> 19070 | S15: =IF(G15=0,"Stockout ⚠",IF(G15<Q15,"Reorder 🔄",IF(G15>Q15+L15,"Overstock 📦","Aman ✅"))) -> Overstock 📦 | T15: =IFERROR(N15/AVERAGE(M12:M16),0) -> 0.21085306 | U15: -2010.59 | V15: 0.428
A16: 5 | B16: 2025 | C16: Lokal | D16: BB002 | E16: Glycerin | F16: kg | G16: 12645 | H16: 41 | I16: =IFERROR(ROUND('Data Bulanan'!EC7,0),0) -> 35127 | J16: 11280718 | K16: 117450 | L16: =IFERROR(ROUND(SQRT(2*I16*J16/K16),0),0) -> 2598 | M16: =IFERROR(AVERAGE('Data Bulanan'!DF7,'Data Bulanan'!DH7,'Data Bulanan'!DJ7,'Data Bulanan'!DL7,'Data Bulanan'!DN7,'Data Bulanan'!DP7,'Data Bulanan'!DR7,'Data Bulanan'!DT7,'Data Bulanan'!DV7,'Data Bulanan'!DX7,'Data Bulanan'!DZ7,'Data Bulanan'!EB7),0) -> 93.490124 | N16: ='Data Bulanan'!ED7 -> 21.95436 | O16: =IFERROR(N16*SQRT(H16),0) -> 140.57649 | P16: =IFERROR(ROUND(1.65*O16,0),0) -> 232 | Q16: =IFERROR(ROUND(M16*H16+P16,0),0) -> 4065 | R16: =G16-Q16 -> 8580 | S16: =IF(G16=0,"Stockout ⚠",IF(G16<Q16,"Reorder 🔄",IF(G16>Q16+L16,"Overstock 📦","Aman ✅"))) -> Overstock 📦 | T16: =IFERROR(N16/AVERAGE(M12:M16),0) -> 0.20450566 | U16: -2010.59 | V16: 0.428
A17: 1 | B17: 2021 | C17: Lokal | D17: BB003 | E17: Cetyl Alcohol | F17: kg | G17: 2265 | H17: 9 | I17: =IFERROR(ROUND('Data Bulanan'!AC8,0),0) -> 35615 | J17: 732974 | K17: 417580 | L17: =IFERROR(ROUND(SQRT(2*I17*J17/K17),0),0) -> 354 | M17: =IFERROR(AVERAGE('Data Bulanan'!F8,'Data Bulanan'!H8,'Data Bulanan'!J8,'Data Bulanan'!L8,'Data Bulanan'!N8,'Data Bulanan'!P8,'Data Bulanan'!R8,'Data Bulanan'!T8,'Data Bulanan'!V8,'Data Bulanan'!X8,'Data Bulanan'!Z8,'Data Bulanan'!AB8),0) -> 94.744259 | N17: ='Data Bulanan'!AD8 -> 26.375842 | O17: =IFERROR(N17*SQRT(H17),0) -> 79.127527 | P17: =IFERROR(ROUND(1.65*O17,0),0) -> 131 | Q17: =IFERROR(ROUND(M17*H17+P17,0),0) -> 984 | R17: =G17-Q17 -> 1281 | S17: =IF(G17=0,"Stockout ⚠",IF(G17<Q17,"Reorder 🔄",IF(G17>Q17+L17,"Overstock 📦","Aman ✅"))) -> Overstock 📦 | T17: =IFERROR(N17/AVERAGE(M17:M21),0) -> 0.32343263 | U17: -706.58 | V17: 0.1042
A18: 2 | B18: 2022 | C18: Lokal | D18: BB003 | E18: Cetyl Alcohol | F18: kg | G18: 1928 | H18: 9 | I18: =IFERROR(ROUND('Data Bulanan'!BC8,0),0) -> 28394 | J18: 760393 | K18: 402234 | L18: =IFERROR(ROUND(SQRT(2*I18*J18/K18),0),0) -> 328 | M18: =IFERROR(AVERAGE('Data Bulanan'!AF8,'Data Bulanan'!AH8,'Data Bulanan'!AJ8,'Data Bulanan'!AL8,'Data Bulanan'!AN8,'Data Bulanan'!AP8,'Data Bulanan'!AR8,'Data Bulanan'!AT8,'Data Bulanan'!AV8,'Data Bulanan'!AX8,'Data Bulanan'!AZ8,'Data Bulanan'!BB8),0) -> 75.825371 | N18: ='Data Bulanan'!BD8 -> 20.395968 | O18: =IFERROR(N18*SQRT(H18),0) -> 61.187904 | P18: =IFERROR(ROUND(1.65*O18,0),0) -> 101 | Q18: =IFERROR(ROUND(M18*H18+P18,0),0) -> 783 | R18: =G18-Q18 -> 1145 | S18: =IF(G18=0,"Stockout ⚠",IF(G18<Q18,"Reorder 🔄",IF(G18>Q18+L18,"Overstock 📦","Aman ✅"))) -> Overstock 📦 | T18: =IFERROR(N18/AVERAGE(M17:M21),0) -> 0.25010468 | U18: -706.58 | V18: 0.1042
A19: 3 | B19: 2023 | C19: Lokal | D19: BB003 | E19: Cetyl Alcohol | F19: kg | G19: 1837 | H19: 9 | I19: =IFERROR(ROUND('Data Bulanan'!CC8,0),0) -> 29339 | J19: 703207 | K19: 390435 | L19: =IFERROR(ROUND(SQRT(2*I19*J19/K19),0),0) -> 325 | M19: =IFERROR(AVERAGE('Data Bulanan'!BF8,'Data Bulanan'!BH8,'Data Bulanan'!BJ8,'Data Bulanan'!BL8,'Data Bulanan'!BN8,'Data Bulanan'!BP8,'Data Bulanan'!BR8,'Data Bulanan'!BT8,'Data Bulanan'!BV8,'Data Bulanan'!BX8,'Data Bulanan'!BZ8,'Data Bulanan'!CB8),0) -> 77.890182 | N19: ='Data Bulanan'!CD8 -> 15.981744 | O19: =IFERROR(N19*SQRT(H19),0) -> 47.945233 | P19: =IFERROR(ROUND(1.65*O19,0),0) -> 79 | Q19: =IFERROR(ROUND(M19*H19+P19,0),0) -> 780 | R19: =G19-Q19 -> 1057 | S19: =IF(G19=0,"Stockout ⚠",IF(G19<Q19,"Reorder 🔄",IF(G19>Q19+L19,"Overstock 📦","Aman ✅"))) -> Overstock 📦 | T19: =IFERROR(N19/AVERAGE(M17:M21),0) -> 0.19597545 | U19: -706.58 | V19: 0.1042
